# 9. 예외 처리

# **목표**

자바의 예외 처리에 대해 학습하세요.

#### 오류 분류

프로그램이 실행 중 어떤 원인에  의해서 오작동을 하거나 비정상적으로 종료되는 경우로, 이 원인을 에러 또는 오류라고 한다.

##### 논리적 에러

실행은 되지만 의도와 다르게 동작하는 경우

##### 컴파일 에러

컴파일 과정에서 일어나는 에러로, 자바 컴파일러가 문법 검사를 통해 잡는다.

##### 런타임 에러

실행 과정에서 일어나는 에러로, 예외와 에러 두 가지로 구분

**에러(Error)**

- 메모리 부족, 스택오버플로우 처럼 JVM이나 하드웨어 등의 기반 시스템의 문제로 발생
- 발생시 복구 불가능하여 프로그램 종료

**예외(Execption)**

- 발생하더라도 프로그래머가 핸들링 가능한 오류

#### 자바에서 예외 처리 방법 (try, catch, throw, throws, finally)

실행 시 발생할 수 있는 오류(Exception, Erorr)를 클래스로 정의하여 오류의 정보 다룬다. 이러한 클래스를 통해 오류를 분류하고 핸들링한다.

##### 예외 계층 구조

**Object**

- **Throwable**
  - **Exception**
    - **RuntimeException**
    - **IOException**
    - **etc**
  - **Error**
    - **OutOfMemoryError**
    - **etc**

**Exception**: 외부 영향으로 발생할 수 있는 예외

- **IOException**
- **ClassNotFounException**
- **RuntimeException**: 프로그래머의 실수로 발생되는 예외(unchecked)
  - **ArithmeticException**
  - **ClassCastException**
  - **IndexOutOfBoundsException**
  - **etc**

발생한 예외를 처리하지 못하면, 프로그램 종료, JVM의 예외처리기가 예외의 원인 출력

##### checked Exception, unchecked Exception

**Exception(checked Exception)**:  컴파일 시점에서 확인될 수 있는 예외

- 코드내에서 `checked Exception` 발생시, 반드시 명시해야 한다(`try-catch`,`throws`)
  - 아니면 컴파일도 안된다

**Runtime Exception(Unchecked Exception)**:  컴파일 시점에서 확인되지 않는 에러

- 프로그래머가 알아서 처리해야 한다
- 프로그래머의 실수로 발생하기 때문에 호출하는 곳에서 해결해야하는것이 아니라, 프로그래머가 복구해야한다.

#### try-catch

try 블럭에 여러 개의 catch 블럭 매칭 가능, 발생한 예외의 종류와 일치하는 catch블록만 수행된다.

예외 발생시 해당 예외에 해당하는 클래스 인스턴스 생성

- `instanceof` 통해 해당 클래스인지 확인 -> 수퍼 클래스가 선언되어도 처리 가능
  - `Exception`으로 catch 블럭 구현시 모든 예외 그 블럭에서 처리

**동작**

`try`블럭에서 예외가 발생한 경우

1. 발생한 예외와 일치하는 `catch`블럭을 찾는다
   - `catch`블록의 명령어 수행후, `try-catch`문 밖의 명령어 수행한다.

2. 일치하는 `catch`블럭 없으면 예외 처리 실패

- 예외 발생하지 않으면 `try-catch` 문 밖의 명령어 수행

```java
try {
    // 예외가 일어날 수 있는 코드
}
catch (Exception1 e1){ // Exception1 예외 클래스, e1: 인스턴스 
    // 참조 변수 e1을 통해 예외의 정보에 접근 가능
    // Exception1가 발생한 경우, 이를 처리하기 위한 핸들러 작성
    // e.printStackTrace() : 예외발생 당시의 호출스택의 메서드 정보, 예외 메시지 출력
    // e1.getMessage() : 발생한 예외클래스의 인스턴스에 저장된 메시지 얻을 수 있다.
}
catch (Exception2 | Exception3 e){ // 여러개의 블럭 하나로 합칠 수 잇다 JDK1.7부터 도입
    // Exception2, Exception3 공통의 부모의 메서드만 사용가능
    // Exception2 핸들러
}
```

#### finally

예외의 발생여부에 상관없이 실행되어야할 코드 포함

- `try-catch`문의 끝에 선택적으로 덧붙인다

**경우**

- `try`문 에러 없이 끝나는 경우

  - ```java
    try {
        System.out.println("main"); // main
    }
    catch (IndexOutOfBoundsException e){
        System.out.println("catch1");
    }
    finally {
        System.out.println("finally"); // finally
    }
    ```

  - ```
    main
    finally
    ```

- `try`문에서 예상치 못한 에러 발생한 경우

  - ```java
    try {
        System.out.println("main");
        System.out.println(1 / 0);
    }
    catch (IndexOutOfBoundsException e){
        System.out.println("catch1");
    
    }
    finally {
        System.out.println("finally");
    }
    ```

  - ```
    main
    finally
    Exception in thread "main" java.lang.ArithmeticException: / by zero
    	at ExceptionTest.main(ExceptionTest.java:5)
    ```

- `try`문에서 `return` 수행

  - ```java
    try {
        System.out.println("main");
        return ;
    }
    catch (IndexOutOfBoundsException e){
        System.out.println("catch1");
    }
    finally {
        System.out.println("finally");
    }
    ```

  - ```
    main
    finally
    ```

#### throw

프로그래머가 고의로 예외 발생가능

**동작**

1. `new`를 통해 발생시키려는 예외 클래스 객체 생성
2. `throw` 통해 예외 발생시킨다

```java
try {
	Exception e = new Exception("throw test"); // 인자로 String 전달 시, 예외의 메시지가 된다
	throw e; // Exception 발생    
}
catch(Exception e){
    System.out.println(e.getMessage()); // throw test
}

```

#### throws

메소드의 선언부에 예외를 선언함으로 해당 메소드를 사용하는 사람들에게 어떤 예외를 처리해야하는지 알림

- 메소드 호출시 예외처리를 강요
  - 메소드 내에서 처리 가능시, 안에서 `try-catch`통하여
  - 외부 값들 필요할 시 밖에서 `try-catch`
  - 결국에는 어느 위치에서는 thows된 예외들에 대해 `try-catch` 되어야 한다.
- 보통 `RuntimeException`클래스는 작성 지양
  - 반드시 처리해야하는 경우만 적어야 하므로

```java
void method() throws Exception1, Exception2, Exception3 {
    // method 내용
}
// ...
// 
try {
    c.method()
}
catch(Exception1 | Exception2 | Exception3){
    // ...
}
```

#### try-with-resource

시스템 자원 사용하는 코드의 경우 `finally`를 통해 예외가 발생하더라도 반드시 자원을 닫도록 했지만, java7부터 `try-with-resource`통해 처리하도록 했다

**괄호**를 통해 선언

```java
try(
// 자원 FileInputStream f = new FileInputStream("file.txt")
){
    // code
}
catch(Exception1 e){
    
}
```

#### 커스텀한 예외 만드는 방법

기존의 예외 클래스 외에 새로운 예외 클래스 정의 가능

`Exception`의 서브 클래스 상속 받아서 구현

- `RuntimeException`을 받아서 unchecked 로 구현하거나
- `Exception`받아서 checked 로 구현하거나

```java
class TestException extends Exception {
    public TestException(String message){
        super(message);
    }
}
```

---

#### 질문

re-throwing

chained Exception

#### 참조

자바의 정석